<?xml version="1.0" encoding="utf-8"?>
<mujoco model="arm29">

  <compiler inertiafromgeom="auto" angle="radian" balanceinertia="true" boundmass="0.001" boundinertia="0.001">
    <lengthrange inttotal="50" useexisting="true"></lengthrange>
  </compiler>

  <default>
    <default class="elbow2d9">
        <joint limited="true" damping="0.1" armature="0.01" stiffness="0"></joint>
        <geom contype="1" conaffinity="0" condim="3" rgba="0.8 0.85 0.8 1" margin="0.001" solref=".02 1" solimp=".8 .8 .01" material="geom"></geom>
        <site size="0.001"></site>
        <tendon width="0.005" rgba=".95 .3 .3 1" limited="false"></tendon>
        <default class="muscle">
          <muscle ctrllimited="true" ctrlrange="0.001 1" scale="1" vmax="15" fvmax="1.4" timeconst="0.01 0.04"></muscle>
        </default>
    </default>
  </default>

  <option timestep="0.002"/>
  <size njmax="1000" nconmax="400" nuser_jnt="1"></size>

  <visual>
    <headlight diffuse="1 1 1"/>
    <scale actuatorwidth=".075"/>
  </visual>

  <worldbody>
    <geom name="floor" pos="0 0 0" size="1 1 0.125" type="plane" material="MatPlane" condim="3"></geom>
    <body name="base" pos="0 4.89859e-17 0.8" quat="0.7071067811865475 0.7071067811865475 0.0 0.0">
      <light mode="trackcom" directional="false" pos="0 0 4.0" dir="0 0 -1"></light>
      <geom name="ground_ribs" type="mesh" mesh="ground_ribs"></geom>
      <geom name="ground_spine" type="mesh" mesh="ground_spine"></geom>
      <geom name="ground_skull" type="mesh" mesh="ground_skull"></geom>
      <geom name="ground_jaw" type="mesh" mesh="ground_jaw"></geom>
      <site name="PECM2-P3" pos="0.0206133 -0.02625 0.120667"></site>
      <site name="PECM2-P4" pos="0.03091 -0.03522 0.09705"></site>
      <site name="PECM2-P5" pos="0.02769 -0.04498 0.02271"></site>
      <site name="TRIlong-P1" pos="-0.05365 -0.01373 0.14723"></site>
      <site name="BIClong-P1" pos="-0.039235 0.00347 0.14795"></site>
      <site name="BIClong-P2" pos="-0.028945 0.01391 0.15639"></site>
	  <site name="r_acromion" pos="-0.01256 0.04 0.17"></site>
      <body name="r_humerus" pos="-0.017545   -0.007     0.17" quat="1.0 0.0 0.0 0.0">
        <geom name="arm_r_humerus" type="mesh" mesh="arm_r_humerus"></geom>
        <inertial pos=" 0 -0.180496  0" mass="1.864572" fullinertia=" 0.01481 0.004551 0.013193 0 0 0"></inertial>
        <site name="DELT1-P1" pos="0.00896 -0.11883 0.00585"></site>
        <site name="DELT1-P2" pos="0.01623 -0.11033 0.00412"></site>
        <site name="DELT3-P3" pos="0.00206 -0.07602 0.01045"></site>
        <site name="TMIN-P1" pos="-0.00127 -0.01259 0.022"></site>
        <site name="PECM2-P1" pos="0.01274 -0.04289 0.00785"></site>
        <site name="PECM2-P2" pos="0.0164967 -0.03878 -0.00207"></site>
        <site name="TRIlong-P2" pos="-0.02714 -0.11441 -0.00664"></site>
        <site name="TRIlong-P3" pos="-0.03184 -0.22637 -0.01217"></site>
        <site name="TRIlong-P4" pos="-0.01743 -0.26757 -0.01208"></site>
        <site name="TRIlat-P1" pos="-0.00599 -0.12646 0.00428"></site>
        <site name="TRIlat-P2" pos="-0.02344 -0.14528 0.00928"></site>
        <site name="TRIlat-P3" pos="-0.03184 -0.22637 -0.01217"></site>
        <site name="TRIlat-P4" pos="-0.01743 -0.26757 -0.01208"></site>
        <site name="BIClong-P3" pos="0.02131 0.01793 0.01028"></site>
        <site name="BIClong-P4" pos="0.02378 -0.00511 0.01201"></site>
        <site name="BIClong-P5" pos="0.01345 -0.02827 0.00136"></site>
        <site name="BIClong-P6" pos="0.01068 -0.07736 -0.00165"></site>
        <site name="BIClong-P7" pos="0.01703 -0.12125 0.00024"></site>
        <site name="BIClong-P8" pos="0.0228 -0.1754 -0.0063"></site>
        <site name="BRA-P1" pos="0.0068 -0.1739 -0.0036"></site>
        <site name="BRD-P1" pos="-0.0098 -0.19963 0.00223"></site>
		<site name="r_humerus_epicondyle" pos="0.005 -0.2904 0.03"></site>
        <joint name="r_shoulder_elev" type="hinge" pos="0 0 0" axis="-0.058898 0.0023 0.998261" limited="true" range=" -1.5708  3.14159" ref="0"></joint>
        <body name="r_ulna_radius_hand" pos="  0.0061  -0.2904  -0.0123" quat="1.0 0.0 0.0 0.0">
          <geom name="arm_r_ulna" type="mesh" mesh="arm_r_ulna"></geom>
          <geom name="arm_r_radius" type="mesh" mesh="arm_r_radius"></geom>
          <geom name="arm_r_lunate" type="mesh" mesh="arm_r_lunate"></geom>
          <geom name="arm_r_scaphoid" type="mesh" mesh="arm_r_scaphoid"></geom>
          <geom name="arm_r_pisiform" type="mesh" mesh="arm_r_pisiform"></geom>
          <geom name="arm_r_triquetrum" type="mesh" mesh="arm_r_triquetrum"></geom>
          <geom name="arm_r_capitate" type="mesh" mesh="arm_r_capitate"></geom>
          <geom name="arm_r_trapezium" type="mesh" mesh="arm_r_trapezium"></geom>
          <geom name="arm_r_trapezoid" type="mesh" mesh="arm_r_trapezoid"></geom>
          <geom name="arm_r_hamate" type="mesh" mesh="arm_r_hamate"></geom>
          <geom name="arm_r_1mc" type="mesh" mesh="arm_r_1mc"></geom>
          <geom name="arm_r_2mc" type="mesh" mesh="arm_r_2mc"></geom>
          <geom name="arm_r_3mc" type="mesh" mesh="arm_r_3mc"></geom>
          <geom name="arm_r_4mc" type="mesh" mesh="arm_r_4mc"></geom>
          <geom name="arm_r_5mc" type="mesh" mesh="arm_r_5mc"></geom>
          <geom name="arm_r_thumbprox" type="mesh" mesh="arm_r_thumbprox"></geom>
          <geom name="arm_r_thumbdist" type="mesh" mesh="arm_r_thumbdist"></geom>
          <geom name="arm_r_2proxph" type="mesh" mesh="arm_r_2proxph"></geom>
          <geom name="arm_r_2midph" type="mesh" mesh="arm_r_2midph"></geom>
          <geom name="arm_r_2distph" type="mesh" mesh="arm_r_2distph"></geom>
          <geom name="arm_r_3proxph" type="mesh" mesh="arm_r_3proxph"></geom>
          <geom name="arm_r_3midph" type="mesh" mesh="arm_r_3midph"></geom>
          <geom name="arm_r_3distph" type="mesh" mesh="arm_r_3distph"></geom>
          <geom name="arm_r_4proxph" type="mesh" mesh="arm_r_4proxph"></geom>
          <geom name="arm_r_4midph" type="mesh" mesh="arm_r_4midph"></geom>
          <geom name="arm_r_4distph" type="mesh" mesh="arm_r_4distph"></geom>
          <geom name="arm_r_5proxph" type="mesh" mesh="arm_r_5proxph"></geom>
          <geom name="arm_r_5midph" type="mesh" mesh="arm_r_5midph"></geom>
          <geom name="arm_r_5distph" type="mesh" mesh="arm_r_5distph"></geom>
          <inertial pos="0 -0.181479 0" mass="1.534315" fullinertia="0.019281 0.001571 0.020062 0 0 0"></inertial>
          <site name="TRIlong-P5" pos="-0.0219 0.01046 -0.00078"></site>
          <site name="TRIlat-P5" pos="-0.0219 0.01046 -0.00078"></site>
          <site name="BIClong-P9" pos="0.00751 -0.04839 0.02179"></site>
          <site name="BRA-P2" pos="-0.0032 -0.0239 0.0009"></site>
          <site name="BRD-P2" pos="0.01 -0.08 0.035"></site>
          <site name="BRD-P3" pos="0.005 -0.16 0.06"></site>
		  <site name="r_radius_styloid" pos="-0.0011 -0.23559 0.0943"></site>
          <joint name="r_elbow_flex" type="hinge" pos="0 0 0" axis=" 0.0494 0.0366 0.998108" limited="true" range="0 2.26893" ref="0"></joint>
        </body>
      </body>
      <body name="clavicle" pos="0.006325  0.00693 0.025465" quat="1.0 0.0 0.0 0.0">
        <geom name="clavicle" type="mesh" mesh="clavicle"></geom>
        <inertial pos="-0.011096 0.0063723 0.054168" mass="0.156" fullinertia="0.00024259 0.00025526 4.442e-05 -1.898e-05 -6.994e-05 5.371e-05"></inertial>
        <site name="DELT1-P4" pos="-0.014 0.01106 0.08021"></site>
        <body name="scapula" pos="-0.01433  0.02007 0.135535" quat="1.0 0.0 0.0 0.0">
          <geom name="scapula" type="mesh" mesh="scapula"></geom>
          <inertial pos="-0.054694 -0.035032 -0.043734" mass="0.70396" fullinertia="0.0012429 0.0011504 0.0013651 0.0004494 0.00040922 0.0002411"></inertial>
          <site name="DELT1-P3" pos="0.04347 -0.03252 0.00099"></site>
          <site name="DELT3-P1" pos="-0.05573 0.00122 -0.02512"></site>
          <site name="DELT3-P2" pos="-0.07247 -0.03285 0.01233"></site>
          <site name="TMIN-P2" pos="-0.09473 -0.07991 -0.04737"></site>
          <site name="TMIN-P3" pos="-0.09643 -0.08121 -0.05298"></site>
        </body>
      </body>
    </body>
    <camera name="for_testing" pos="0 0 0" euler="0 0 0"></camera>
  </worldbody>
  <asset>
    <mesh name="ground_ribs" file="Geometry/ground_ribs.stl" scale=" 1 1 1"></mesh>
    <mesh name="ground_spine" file="Geometry/ground_spine.stl" scale=" 1 1 1"></mesh>
    <mesh name="ground_skull" file="Geometry/ground_skull.stl" scale=" 1 1 1"></mesh>
    <mesh name="ground_jaw" file="Geometry/ground_jaw.stl" scale=" 1 1 1"></mesh>
    <mesh name="arm_r_humerus" file="Geometry/arm_r_humerus.stl" scale=" 1 1 1"></mesh>
    <mesh name="arm_r_ulna" file="Geometry/arm_r_ulna.stl" scale=" 1 1 1"></mesh>
    <mesh name="arm_r_radius" file="Geometry/arm_r_radius.stl" scale=" 1 1 1"></mesh>
    <mesh name="arm_r_lunate" file="Geometry/arm_r_lunate.stl" scale=" 1 1 1"></mesh>
    <mesh name="arm_r_scaphoid" file="Geometry/arm_r_scaphoid.stl" scale=" 1 1 1"></mesh>
    <mesh name="arm_r_pisiform" file="Geometry/arm_r_pisiform.stl" scale=" 1 1 1"></mesh>
    <mesh name="arm_r_triquetrum" file="Geometry/arm_r_triquetrum.stl" scale=" 1 1 1"></mesh>
    <mesh name="arm_r_capitate" file="Geometry/arm_r_capitate.stl" scale=" 1 1 1"></mesh>
    <mesh name="arm_r_trapezium" file="Geometry/arm_r_trapezium.stl" scale=" 1 1 1"></mesh>
    <mesh name="arm_r_trapezoid" file="Geometry/arm_r_trapezoid.stl" scale=" 1  1  1"></mesh>
    <mesh name="arm_r_hamate" file="Geometry/arm_r_hamate.stl" scale=" 1  1  1"></mesh>
    <mesh name="arm_r_1mc" file="Geometry/arm_r_1mc.stl" scale=" 1  1  1"></mesh>
    <mesh name="arm_r_2mc" file="Geometry/arm_r_2mc.stl" scale=" 1 1  1"></mesh>
    <mesh name="arm_r_3mc" file="Geometry/arm_r_3mc.stl" scale=" 1 1  1"></mesh>
    <mesh name="arm_r_4mc" file="Geometry/arm_r_4mc.stl" scale=" 1 1  1"></mesh>
    <mesh name="arm_r_5mc" file="Geometry/arm_r_5mc.stl" scale=" 1 1  1"></mesh>
    <mesh name="arm_r_thumbprox" file="Geometry/arm_r_thumbprox.stl" scale=" 1  1  1"></mesh>
    <mesh name="arm_r_thumbdist" file="Geometry/arm_r_thumbdist.stl" scale=" 1  1  1"></mesh>
    <mesh name="arm_r_2proxph" file="Geometry/arm_r_2proxph.stl" scale=" 1  1  1"></mesh>
    <mesh name="arm_r_2midph" file="Geometry/arm_r_2midph.stl" scale=" 1  1  1"></mesh>
    <mesh name="arm_r_2distph" file="Geometry/arm_r_2distph.stl" scale=" 1  1  1"></mesh>
    <mesh name="arm_r_3proxph" file="Geometry/arm_r_3proxph.stl" scale=" 1  1  1"></mesh>
    <mesh name="arm_r_3midph" file="Geometry/arm_r_3midph.stl" scale=" 1  1  1"></mesh>
    <mesh name="arm_r_3distph" file="Geometry/arm_r_3distph.stl" scale=" 1  1  1"></mesh>
    <mesh name="arm_r_4proxph" file="Geometry/arm_r_4proxph.stl" scale=" 1  1  1"></mesh>
    <mesh name="arm_r_4midph" file="Geometry/arm_r_4midph.stl" scale=" 1  1  1"></mesh>
    <mesh name="arm_r_4distph" file="Geometry/arm_r_4distph.stl" scale=" 1  1  1"></mesh>
    <mesh name="arm_r_5proxph" file="Geometry/arm_r_5proxph.stl" scale=" 1  1  1"></mesh>
    <mesh name="arm_r_5midph" file="Geometry/arm_r_5midph.stl" scale=" 1  1  1"></mesh>
    <mesh name="arm_r_5distph" file="Geometry/arm_r_5distph.stl" scale=" 1  1  1"></mesh>
    <mesh name="clavicle" file="Geometry/clavicle.stl" scale=" 1 1 1"></mesh>
    <mesh name="scapula" file="Geometry/scapula.stl" scale=" 1 1 1"></mesh>
    <texture name="texplane" type="2d" builtin="checker" rgb1=".2 .3 .4" rgb2=".1 0.15 0.2" width="100" height="100"></texture>
    <material name="MatPlane" reflectance="0.0" texture="texplane" texrepeat="1 1" texuniform="true"></material>
  </asset>
  <tendon>
    <spatial name="DELT1_tendon" rgba="0.95 0.3 0.3 41" >
      <site site="DELT1-P1"></site>
      <site site="DELT1-P2"></site>
      <site site="DELT1-P3"></site>
      <site site="DELT1-P4"></site>
    </spatial>
    <spatial name="DELT3_tendon" rgba="0.95 0.3 0.3 41" >
      <site site="DELT3-P1"></site>
      <site site="DELT3-P2"></site>
      <site site="DELT3-P3"></site>
    </spatial>
    <spatial name="TMIN_tendon" rgba="0.95 0.3 0.3 41" >
      <site site="TMIN-P1"></site>
      <site site="TMIN-P2"></site>
      <site site="TMIN-P3"></site>
    </spatial>
    <spatial name="PECM2_tendon" rgba="0.95 0.3 0.3 41" >
      <site site="PECM2-P1"></site>
      <site site="PECM2-P2"></site>
      <site site="PECM2-P3"></site>
      <site site="PECM2-P4"></site>
      <site site="PECM2-P5"></site>
    </spatial>
    <spatial name="TRIlong_tendon" rgba="0.95 0.3 0.3 41" >
      <site site="TRIlong-P1"></site>
      <site site="TRIlong-P2"></site>
      <site site="TRIlong-P3"></site>
      <site site="TRIlong-P4"></site>
      <site site="TRIlong-P5"></site>
    </spatial>
    <spatial name="TRIlat_tendon" rgba="0.95 0.3 0.3 41" >
      <site site="TRIlat-P1"></site>
      <site site="TRIlat-P2"></site>
      <site site="TRIlat-P3"></site>
      <site site="TRIlat-P4"></site>
      <site site="TRIlat-P5"></site>
    </spatial>
    <spatial name="BIClong_tendon" rgba="0.95 0.3 0.3 41" >
      <site site="BIClong-P1"></site>
      <site site="BIClong-P2"></site>
      <site site="BIClong-P3"></site>
      <site site="BIClong-P4"></site>
      <site site="BIClong-P5"></site>
      <site site="BIClong-P6"></site>
      <site site="BIClong-P7"></site>
      <site site="BIClong-P8"></site>
      <site site="BIClong-P9"></site>
    </spatial>
    <spatial name="BRA_tendon" rgba="0.95 0.3 0.3 41">
      <site site="BRA-P1"></site>
      <site site="BRA-P2"></site>
    </spatial>
    <spatial name="BRD_tendon" rgba="0.95 0.3 0.3 41">
      <site site="BRD-P1"></site>
      <site site="BRD-P2"></site>
      <site site="BRD-P3"></site>
    </spatial>
  </tendon>
  <actuator>
    <muscle name="DELT1" tendon="DELT1_tendon" class="muscle" timeconst=" 0.01 0.04" force="277.48" lengthrange="0.161055 0.297166" ctrllimited="true" ctrlrange=" 0.01 1"></muscle>
    <muscle name="DELT3" tendon="DELT3_tendon" class="muscle" timeconst=" 0.01 0.04" force="201.6" lengthrange="0.103005 0.233014" ctrllimited="true" ctrlrange=" 0.01 1"></muscle>
    <muscle name="TMIN" tendon="TMIN_tendon" class="muscle" timeconst=" 0.01 0.04" force="269.5" lengthrange="0.105147 0.172841" ctrllimited="true" ctrlrange=" 0.01 1"></muscle>
    <muscle name="PECM2" tendon="PECM2_tendon" class="muscle" timeconst=" 0.01 0.04" force="658.3" lengthrange="0.151241 0.275724" ctrllimited="true" ctrlrange=" 0.01 1"></muscle>
    <muscle name="TRIlong" tendon="TRIlong_tendon" class="muscle" timeconst=" 0.01 0.04" force="798.52" lengthrange="0.208536 0.339608" ctrllimited="true" ctrlrange=" 0.01 1"></muscle>
    <muscle name="TRIlat" tendon="TRIlat_tendon" class="muscle" timeconst=" 0.01 0.04" force="624.3" lengthrange="0.154199 0.266598" ctrllimited="true" ctrlrange=" 0.01 1"></muscle>
    <muscle name="BIClong" tendon="BIClong_tendon" class="muscle" timeconst=" 0.01 0.04" force="624.3" lengthrange=" 0.33015  0.44585" ctrllimited="true" ctrlrange=" 0.01 1"></muscle>
    <muscle name="BRA" tendon="BRA_tendon" class="muscle" timeconst=" 0.01 0.04" force="987.26" lengthrange="  0.0964   0.1822" ctrllimited="true" ctrlrange=" 0.01 1"></muscle>
    <muscle name="BRD" tendon="BRD_tendon" class="muscle" timeconst=" 0.01 0.04" force="276" lengthrange="  0.2193   0.3919" ctrllimited="true" ctrlrange=" 0.01 1"></muscle>
  </actuator>
  <equality>
    <weld name="origin_to_worldbody" body1="base" active="false"></weld>
  </equality>
</mujoco>